from django.test import TestCase
from ..classes import site_mappers
from ..exceptions import MapperError

class MapperTests(TestCase):

    def test_mapper_methods(self):
        site_mappers.autodiscover()
        mapper = site_mappers.get_registry('otse')()
        lat = None
        lon = None
        
        #Test gps_distance_between_points(self, lat, lon, center_lat=None, center_lon=None, radius=None): method
        self.assertRaises(MapperError, mapper.gps_distance_between_points, lat, lon)
        self.assertEqual(mapper.gps_distance_between_points(-24.656637, 25.924327, -24.656366, 25.922935), 0.14407256837110122, 'Correct distance if matching')
        #Test deg_to_dm(dd) method
        self.assertEqual(mapper.deg_to_dm(-24.656637), [24.0, 39.39822000000004], 'converted to this: -24.656637 to this : 24.0, 39.39822000000004]')
        #Test get_cardinal_point_direction(self, start_lat, start_lon, end_lat, end_lon) method
        self.assertEqual(mapper.get_cardinal_point_direction(-24.656637, 25.924327, -24.656366, 25.922935), (0.144, 'W'), 'Direction and distance between two point')
        #Test verify_gps_to_target(self, lat, lon, center_lat, center_lon, radius, exception_cls)
        #self.assertRaises(MapperError, mapper.verify_gps_to_target, -24.656637, 25.924327, -24.656366, 25.922935, 0.025, MapperError)
        self.assertEqual(mapper.verify_gps_to_target(-24.656637, 25.924327, -24.656637, 25.924327, 0.025, MapperError), True, 'The is the same point targeted')